<?xml version="1.0" encoding="utf-8"?>
<!-- This URDF was automatically created by SolidWorks to URDF Exporter! Originally created by Stephen Brawner (brawner@gmail.com) 
     Commit Version: 1.6.0-4-g7f85cfe  Build Version: 1.6.7995.38578
     For more information, please see http://wiki.ros.org/sw_urdf_exporter -->
<robot
  name="urdf_assem4_18">
  <link
    name="base_link">
    <inertial>
      <origin
        xyz="-4.42306624898192E-06 0.0325082852604025 -0.0319372315531231"
        rpy="0 0 0" />
      <mass
        value="0.470910456151114" />
      <inertia
        ixx="0.000790638980684967"
        ixy="-3.51183075880627E-10"
        ixz="4.0781706440438E-08"
        iyy="0.00142015693472341"
        iyz="-4.98244876223888E-08"
        izz="0.00124740964011311" />
    </inertial>
    <visual>
      <origin
        xyz="0 0 0"
        rpy="0 0 0" />
      <geometry>
        <mesh
          filename="package://urdf_assem4_18/meshes/base_link.STL" />
      </geometry>
      <material
        name="">
        <color
          rgba="0.792156862745098 0.819607843137255 0.933333333333333 1" />
      </material>
    </visual>
    <collision>
      <origin
        xyz="0 0 0"
        rpy="0 0 0" />
      <geometry>
        <mesh
          filename="package://urdf_assem4_18/meshes/base_link.STL" />
      </geometry>
    </collision>
  </link>
  <link
    name="Link_1">
    <inertial>
      <origin
        xyz="0.026857 -0.0125 0.028768"
        rpy="0 0 0" />
      <mass
        value="0.083064" />
      <inertia
        ixx="3.9402E-05"
        ixy="-1.2792E-20"
        ixz="-2.3972E-05"
        iyy="6.6855E-05"
        iyz="-1.5866E-20"
        izz="3.6105E-05" />
    </inertial>
    <visual>
      <origin
        xyz="0 0 0"
        rpy="0 0 0" />
      <geometry>
        <mesh
          filename="package://urdf_assem4_18/meshes/Link_1.STL" />
      </geometry>
      <material
        name="">
        <color
          rgba="0.79216 0.81961 0.93333 1" />
      </material>
    </visual>
    <collision>
      <origin
        xyz="0 0 0"
        rpy="0 0 0" />
      <geometry>
        <mesh
          filename="package://urdf_assem4_18/meshes/Link_1.STL" />
      </geometry>
    </collision>
  </link>
  <joint
    name="Joint_1"
    type="continuous">
    <origin
      xyz="0.096 0.044532 -0.00625"
      rpy="0 0 0" />
    <parent
      link="base_link" />
    <child
      link="Link_1" />
    <axis
      xyz="0 -1 0" />
  </joint>
  <link
    name="Link_2">
    <inertial>
      <origin
        xyz="-0.0096344 0.0125 0.038159"
        rpy="0 0 0" />
      <mass
        value="0.083064" />
      <inertia
        ixx="5.8902E-05"
        ixy="2.0276E-20"
        ixz="1.1406E-05"
        iyy="6.6855E-05"
        iyz="-6.7174E-20"
        izz="1.6605E-05" />
    </inertial>
    <visual>
      <origin
        xyz="0 0 0"
        rpy="0 0 0" />
      <geometry>
        <mesh
          filename="package://urdf_assem4_18/meshes/Link_2.STL" />
      </geometry>
      <material
        name="">
        <color
          rgba="0.79216 0.81961 0.93333 1" />
      </material>
    </visual>
    <collision>
      <origin
        xyz="0 0 0"
        rpy="0 0 0" />
      <geometry>
        <mesh
          filename="package://urdf_assem4_18/meshes/Link_2.STL" />
      </geometry>
    </collision>
  </link>
  <joint
    name="Joint_2"
    type="continuous">
    <origin
      xyz="0.053739 0 0.057562"
      rpy="0 0 0" />
    <parent
      link="Link_1" />
    <child
      link="Link_2" />
    <axis
      xyz="0 -1 0" />
  </joint>
  <link
    name="Link_3">
    <inertial>
      <origin
        xyz="-0.00073931 -0.0125 0.03935"
        rpy="0 0 0" />
      <mass
        value="0.083064" />
      <inertia
        ixx="6.1765E-05"
        ixy="1.4162E-21"
        ixz="9.0257E-07"
        iyy="6.6855E-05"
        iyz="-2.4669E-20"
        izz="1.3742E-05" />
    </inertial>
    <visual>
      <origin
        xyz="0 0 0"
        rpy="0 0 0" />
      <geometry>
        <mesh
          filename="package://urdf_assem4_18/meshes/Link_3.STL" />
      </geometry>
      <material
        name="">
        <color
          rgba="0.79216 0.81961 0.93333 1" />
      </material>
    </visual>
    <collision>
      <origin
        xyz="0 0 0"
        rpy="0 0 0" />
      <geometry>
        <mesh
          filename="package://urdf_assem4_18/meshes/Link_3.STL" />
      </geometry>
    </collision>
  </link>
  <joint
    name="Joint_3"
    type="continuous">
    <origin
      xyz="-0.019277 -0.0004 0.076352"
      rpy="0 0 0" />
    <parent
      link="Link_2" />
    <child
      link="Link_3" />
    <axis
      xyz="0 -1 0" />
  </joint>
  <link
    name="Link_4">
    <inertial>
      <origin
        xyz="0.017066 -0.0125 0.035503"
        rpy="0 0 0" />
      <mass
        value="0.083064" />
      <inertia
        ixx="5.2762E-05"
        ixy="8.1596E-22"
        ixz="-1.8765E-05"
        iyy="6.6855E-05"
        iyz="1.3527E-21"
        izz="2.2746E-05" />
    </inertial>
    <visual>
      <origin
        xyz="0 0 0"
        rpy="0 0 0" />
      <geometry>
        <mesh
          filename="package://urdf_assem4_18/meshes/Link_4.STL" />
      </geometry>
      <material
        name="">
        <color
          rgba="0.79216 0.81961 0.93333 1" />
      </material>
    </visual>
    <collision>
      <origin
        xyz="0 0 0"
        rpy="0 0 0" />
      <geometry>
        <mesh
          filename="package://urdf_assem4_18/meshes/Link_4.STL" />
      </geometry>
    </collision>
  </link>
  <joint
    name="Joint_4"
    type="continuous">
    <origin
      xyz="-0.096 0.045405 -0.00625"
      rpy="0 0 0" />
    <parent
      link="base_link" />
    <child
      link="Link_4" />
    <axis
      xyz="0 -1 0" />
  </joint>
  <link
    name="Link_5">
    <inertial>
      <origin
        xyz="-0.0085402 0.0125 0.038455"
        rpy="0 0 0" />
      <mass
        value="0.083064" />
      <inertia
        ixx="5.9523E-05"
        ixy="-5.5406E-22"
        ixz="1.0171E-05"
        iyy="6.6855E-05"
        iyz="2.9462E-22"
        izz="1.5984E-05" />
    </inertial>
    <visual>
      <origin
        xyz="0 0 0"
        rpy="0 0 0" />
      <geometry>
        <mesh
          filename="package://urdf_assem4_18/meshes/Link_5.STL" />
      </geometry>
      <material
        name="">
        <color
          rgba="0.79216 0.81961 0.93333 1" />
      </material>
    </visual>
    <collision>
      <origin
        xyz="0 0 0"
        rpy="0 0 0" />
      <geometry>
        <mesh
          filename="package://urdf_assem4_18/meshes/Link_5.STL" />
      </geometry>
    </collision>
  </link>
  <joint
    name="Joint_5"
    type="continuous">
    <origin
      xyz="0.034117 0.00012463 0.070974"
      rpy="0 0 0" />
    <parent
      link="Link_4" />
    <child
      link="Link_5" />
    <axis
      xyz="0 -1 0" />
  </joint>
  <link
    name="Link_6">
    <inertial>
      <origin
        xyz="0.01467 -0.0125 0.036558"
        rpy="0 0 0" />
      <mass
        value="0.083064" />
      <inertia
        ixx="5.5116E-05"
        ixy="-2.5144E-21"
        ixz="-1.661E-05"
        iyy="6.6855E-05"
        iyz="1.8897E-21"
        izz="2.0391E-05" />
    </inertial>
    <visual>
      <origin
        xyz="0 0 0"
        rpy="0 0 0" />
      <geometry>
        <mesh
          filename="package://urdf_assem4_18/meshes/Link_6.STL" />
      </geometry>
      <material
        name="">
        <color
          rgba="0.79216 0.81961 0.93333 1" />
      </material>
    </visual>
    <collision>
      <origin
        xyz="0 0 0"
        rpy="0 0 0" />
      <geometry>
        <mesh
          filename="package://urdf_assem4_18/meshes/Link_6.STL" />
      </geometry>
    </collision>
  </link>
  <joint
    name="Joint_6"
    type="continuous">
    <origin
      xyz="-0.017073 -0.0004 0.076875"
      rpy="0 0 0" />
    <parent
      link="Link_5" />
    <child
      link="Link_6" />
    <axis
      xyz="0 -1 0" />
  </joint>
</robot>